<?xml version="1.0" encoding="UTF-8"?>
<!-- Generated by org.testng.reporters.JUnitReportReporter -->
<testsuite skipped="5" hostname="DESKTOP-J3P0HRF" name="demo.TestNGRetryFailedDemo" tests="8" failures="1" timestamp="2020-04-08T17:54:12 PDT" time="0.026" errors="1">
  <testcase name="test3" time="0.003" classname="demo.TestNGRetryFailedDemo">
    <skipped/>
  </testcase> <!-- test3 -->
  <system-out/>
  <testcase name="test3" time="0.001" classname="demo.TestNGRetryFailedDemo">
    <failure type="java.lang.AssertionError" message="expected [true] but found [false]">
      <![CDATA[java.lang.AssertionError: expected [true] but found [false]
at org.testng.Assert.fail(Assert.java:97)
at org.testng.Assert.failNotEquals(Assert.java:969)
at org.testng.Assert.assertTrue(Assert.java:43)
at org.testng.Assert.assertTrue(Assert.java:53)
at demo.TestNGRetryFailedDemo.test3(TestNGRetryFailedDemo.java:24)
at sun.reflect.NativeMethodAccessorImpl.invoke0(Native Method)
at sun.reflect.NativeMethodAccessorImpl.invoke(Unknown Source)
at sun.reflect.DelegatingMethodAccessorImpl.invoke(Unknown Source)
at java.lang.reflect.Method.invoke(Unknown Source)
at org.testng.internal.MethodInvocationHelper.invokeMethod(MethodInvocationHelper.java:134)
at org.testng.internal.TestInvoker.invokeMethod(TestInvoker.java:597)
at org.testng.internal.TestInvoker.retryFailed(TestInvoker.java:213)
at org.testng.internal.MethodRunner.runInSequence(MethodRunner.java:58)
at org.testng.internal.TestInvoker$MethodInvocationAgent.invoke(TestInvoker.java:816)
at org.testng.internal.TestInvoker.invokeTestMethods(TestInvoker.java:146)
at org.testng.internal.TestMethodWorker.invokeTestMethods(TestMethodWorker.java:146)
at org.testng.internal.TestMethodWorker.run(TestMethodWorker.java:128)
at java.util.ArrayList.forEach(Unknown Source)
at org.testng.TestRunner.privateRun(TestRunner.java:766)
at org.testng.TestRunner.run(TestRunner.java:587)
at org.testng.SuiteRunner.runTest(SuiteRunner.java:384)
at org.testng.SuiteRunner.runSequentially(SuiteRunner.java:378)
at org.testng.SuiteRunner.privateRun(SuiteRunner.java:337)
at org.testng.SuiteRunner.run(SuiteRunner.java:286)
at org.testng.SuiteRunnerWorker.runSuite(SuiteRunnerWorker.java:53)
at org.testng.SuiteRunnerWorker.run(SuiteRunnerWorker.java:96)
at org.testng.TestNG.runSuitesSequentially(TestNG.java:1187)
at org.testng.TestNG.runSuitesLocally(TestNG.java:1109)
at org.testng.TestNG.runSuites(TestNG.java:1039)
at org.testng.TestNG.run(TestNG.java:1007)
at org.testng.remote.AbstractRemoteTestNG.run(AbstractRemoteTestNG.java:115)
at org.testng.remote.RemoteTestNG.initAndRun(RemoteTestNG.java:251)
at org.testng.remote.RemoteTestNG.main(RemoteTestNG.java:77)
]]>
    </failure>
  </testcase> <!-- test3 -->
  <system-out/>
  <testcase name="test3" time="0.001" classname="demo.TestNGRetryFailedDemo">
    <skipped/>
  </testcase> <!-- test3 -->
  <system-out/>
  <testcase name="test1" time="0.012" classname="demo.TestNGRetryFailedDemo"/>
  <system-out/>
  <testcase name="test3" time="0.001" classname="demo.TestNGRetryFailedDemo">
    <skipped/>
  </testcase> <!-- test3 -->
  <system-out/>
  <testcase name="test3" time="0.001" classname="demo.TestNGRetryFailedDemo">
    <skipped/>
  </testcase> <!-- test3 -->
  <system-out/>
  <testcase name="test2" time="0.002" classname="demo.TestNGRetryFailedDemo">
    <error type="java.lang.ArithmeticException" message="/ by zero">
      <![CDATA[java.lang.ArithmeticException: / by zero
at demo.TestNGRetryFailedDemo.test2(TestNGRetryFailedDemo.java:18)
at sun.reflect.NativeMethodAccessorImpl.invoke0(Native Method)
at sun.reflect.NativeMethodAccessorImpl.invoke(Unknown Source)
at sun.reflect.DelegatingMethodAccessorImpl.invoke(Unknown Source)
at java.lang.reflect.Method.invoke(Unknown Source)
at org.testng.internal.MethodInvocationHelper.invokeMethod(MethodInvocationHelper.java:134)
at org.testng.internal.TestInvoker.invokeMethod(TestInvoker.java:597)
at org.testng.internal.TestInvoker.invokeTestMethod(TestInvoker.java:173)
at org.testng.internal.MethodRunner.runInSequence(MethodRunner.java:46)
at org.testng.internal.TestInvoker$MethodInvocationAgent.invoke(TestInvoker.java:816)
at org.testng.internal.TestInvoker.invokeTestMethods(TestInvoker.java:146)
at org.testng.internal.TestMethodWorker.invokeTestMethods(TestMethodWorker.java:146)
at org.testng.internal.TestMethodWorker.run(TestMethodWorker.java:128)
at java.util.ArrayList.forEach(Unknown Source)
at org.testng.TestRunner.privateRun(TestRunner.java:766)
at org.testng.TestRunner.run(TestRunner.java:587)
at org.testng.SuiteRunner.runTest(SuiteRunner.java:384)
at org.testng.SuiteRunner.runSequentially(SuiteRunner.java:378)
at org.testng.SuiteRunner.privateRun(SuiteRunner.java:337)
at org.testng.SuiteRunner.run(SuiteRunner.java:286)
at org.testng.SuiteRunnerWorker.runSuite(SuiteRunnerWorker.java:53)
at org.testng.SuiteRunnerWorker.run(SuiteRunnerWorker.java:96)
at org.testng.TestNG.runSuitesSequentially(TestNG.java:1187)
at org.testng.TestNG.runSuitesLocally(TestNG.java:1109)
at org.testng.TestNG.runSuites(TestNG.java:1039)
at org.testng.TestNG.run(TestNG.java:1007)
at org.testng.remote.AbstractRemoteTestNG.run(AbstractRemoteTestNG.java:115)
at org.testng.remote.RemoteTestNG.initAndRun(RemoteTestNG.java:251)
at org.testng.remote.RemoteTestNG.main(RemoteTestNG.java:77)
]]>
    </error>
  </testcase> <!-- test2 -->
  <system-out/>
  <testcase name="test3" time="0.005" classname="demo.TestNGRetryFailedDemo">
    <skipped/>
  </testcase> <!-- test3 -->
  <system-out/>
</testsuite> <!-- demo.TestNGRetryFailedDemo -->
